#BUG : auth_user error with Django 1.8 and syncdb / migrate
python manage.py migrate auth
python manage.py migrate